<?xml version="1.0" encoding="utf-8"?>
<!-- =================================================================================== -->
<!-- |    This document was autogenerated by xacro from medium_block.xacro             | -->
<!-- |    EDITING THIS FILE BY HAND IS NOT RECOMMENDED                                 | -->
<!-- =================================================================================== -->
<robot name="small_block">
  <material name="blue">
    <color rgba="0 0 0.8 1"/>
  </material>
  <material name="black">
    <color rgba="0 0 0 1"/>
  </material>
  <material name="white">
    <color rgba="1 1 1 1"/>
  </material>
  <link name="base_link">
    <origin rpy="0 0 0" xyz="0 0 0"/>
    <inertial>
      <origin rpy="0 0 0" xyz="0 0 0"/>
      <mass value="0"/>
      <inertia ixx="0" ixy="0" ixz="0" iyy="0" iyz="0" izz="0"/>
    </inertial>
  </link>
  <joint name="base_to_cube_x" type="prismatic">
    <parent link="base_link"/>
    <child link="x_to_y"/>
    <origin rpy="0 0 0" xyz="0 0 0"/>
    <limit effort="1000" lower="-50" upper="50" velocity="10"/>
    <axis xyz="1 0 0"/>
  </joint>
  <link name="x_to_y">
    <origin rpy="0 0 0" xyz="0 0 0"/>
    <inertial>
      <origin rpy="0 0 0" xyz="0 0 0"/>
      <mass value="0"/>
      <inertia ixx="0" ixy="0" ixz="0" iyy="0" iyz="0" izz="0"/>
    </inertial>
  </link>
  <joint name="base_to_cube_y" type="prismatic">
    <parent link="x_to_y"/>
    <child link="y_to_z"/>
    <origin rpy="0 0 1.57079632679" xyz="0 0 0"/>
    <limit effort="1000" lower="-50" upper="50" velocity="10"/>
    <axis xyz="1 0 0"/>
  </joint>
  <link name="y_to_z">
    <origin rpy="0 0 0" xyz="0 0 0"/>
    <inertial>
      <origin rpy="0 0 0" xyz="0 0 0"/>
      <mass value="0"/>
      <inertia ixx="0" ixy="0" ixz="0" iyy="0" iyz="0" izz="0"/>
    </inertial>
  </link>
  <joint name="base_to_cube_z" type="prismatic">
    <parent link="y_to_z"/>
    <child link="block"/>
    <origin rpy="0 -1.57079632679 0 " xyz="0 0 0"/>
    <limit effort="1000" lower="-50" upper="50" velocity="10"/>
    <axis xyz="1 0 0"/>
  </joint>
  <link name="block">
    <visual>
      <geometry>
        <box size="0.04 0.04 0.04"/>
      </geometry>
      <material name="white"/>
    </visual>
    <collision>
      <geometry>
        <box size="0.06 0.06 0.06"/>
      </geometry>
    </collision>
    <inertial>
      <origin rpy="0 0 0" xyz="0 0 0"/>
      <mass value="1"/>
      <inertia ixx="0" ixy="0" ixz="0" iyy="0" iyz="0" izz="0"/>
    </inertial>
    <origin rpy="0 0 0" xyz="0 0 0"/>
  </link>
</robot>

